Workbook
Name Category: 'Material Input (2)'!$B$2
Name Category: 'Material Input'!$B$2
Name Client_Name: 'Material Input (2)'!$B$1
Name Client_Name: 'Material Input'!$B$1
Name End_Clamp: 'Material Input (2)'!$B$15
Name End_Clamp: 'Material Input'!$B$15
Name Grounding_Clip: 'Material Input (2)'!$B$16
Name Grounding_Clip: 'Material Input'!$B$16
Name Grounding_Lug: 'Material Input (2)'!$B$17
Name Grounding_Lug: 'Material Input'!$B$17
Name Klip_Lok_Clamp: 'Material Input (2)'!$B$8
Name Klip_Lok_Clamp: 'Material Input'!$B$8
Name L_Foot: 'Material Input (2)'!$B$7
Name L_Foot: 'Material Input'!$B$7
Name Mid_Clamp: 'Material Input (2)'!$B$14
Name Mid_Clamp: 'Material Input'!$B$14
Name Precast_Concrete_Block: 'Material Input (2)'!$B$18
Name Precast_Concrete_Block: 'Material Input'!$B$18
Name Rail: 'Material Input (2)'!$B$9
Name Rail: 'Material Input'!$B$9
Name Rail_2.6: 'Material Input (2)'!$B$9
Name Rail_2.6: 'Material Input'!$B$9
Name Rail_26: 'Material Input (2)'!$B$9
Name Rail_26: 'Material Input'!$B$9
Name Rail_36: 'Material Input (2)'!$B$12
Name Rail_36: 'Material Input'!$B$12
Name Rail_47: 'Material Input (2)'!$B$11
Name Rail_47: 'Material Input'!$B$11
Name Rail_53: 'Material Input (2)'!$B$10
Name Rail_53: 'Material Input'!$B$10
Name Roof_Type: 'Material Input (2)'!$B$3
Name Roof_Type: 'Material Input'!$B$3
Name Splicer: 'Material Input (2)'!$B$13
Name Splicer: 'Material Input'!$B$13
Name Tile_Hook: 'Material Input (2)'!$B$6
Name Tile_Hook: 'Material Input'!$B$6

Sheet Dashboard
W3: Residential | Z3: =B37 -> 3635.145
W8: C&I | Z8: =B38 -> 3718.01
B35: System Capacity | H35: Project Value (RM) | N35: Revenue (RM) | T35: Collection (RM) | Z35: No of Sites
B36: Total | C36: 2023 | D36: 2024 | E36: 2025 | F36: 2026 | H36: Total | I36: 2023 | J36: 2024 | K36: 2025 | L36: 2026 | N36: Total | O36: 2023 | P36: 2024 | Q36: 2025 | R36: 2026 | T36: Total | U36: 2023 | V36: 2024 | W36: 2025 | X36: 2026 | Z36: Total | AA36: 2023 | AB36: 2024 | AC36: 2025 | AD36: 2026
A37: Residential (PV System) | B37: =SUMIFS(Table1[PV System Capacity (kWp)],Table1[Category],"*R*") -> 3635.145 | C37: =SUMIFS(Table1[PV System Capacity (kWp)],Table1[Category],"*R*",Table1[Closed Date],">="&DATE(2023,1,1),Table1[Closed Date],"<="&DATE(2023,12,31)) -> 313.3 | D37: =SUMIFS(Table1[PV System Capacity (kWp)],Table1[Category],"*R*",Table1[Closed Date],">="&DATE(2024,1,1),Table1[Closed Date],"<="&DATE(2024,12,31)) -> 1637.165 | E37: =SUMIFS(Table1[PV System Capacity (kWp)],Table1[Category],"*R*",Table1[Closed Date],">="&DATE(2025,1,1),Table1[Closed Date],"<="&DATE(2025,12,31)) -> 1684.68 | F37: =SUMIFS(Table1[PV System Capacity (kWp)],Table1[Category],"*R*",Table1[Closed Date],">="&DATE(2026,1,1),Table1[Closed Date],"<="&DATE(2026,12,31)) -> 0 | H37: =SUMIFS(Table1[Project Value (RM)],Table1[Category],"R-PV") -> 10314868 | I37: =SUMIFS(Table1[Project Value (RM)],Table1[Category],"R-PV",Table1[Closed Date],">="&DATE(2023,1,1),Table1[Closed Date],"<="&DATE(2023,12,31)) -> 782725 | J37: =SUMIFS(Table1[Project Value (RM)],Table1[Category],"R-PV",Table1[Closed Date],">="&DATE(2024,1,1),Table1[Closed Date],"<="&DATE(2024,12,31)) -> 5036797.2 | K37: =SUMIFS(Table1[Project Value (RM)],Table1[Category],"R-PV",Table1[Closed Date],">="&DATE(2025,1,1),Table1[Closed Date],"<="&DATE(2025,12,31)) -> 4495345.4 | L37: =SUMIFS(Table1[Project Value (RM)],Table1[Category],"R-PV",Table1[Closed Date],">="&DATE(2026,1,1),Table1[Closed Date],"<="&DATE(2026,12,31)) -> 0 | N37: =SUM(O37:R37) -> 8802124.6 | O37: =SUMIFS('Finance Tracker'!M:M,'Finance Tracker'!L:L,">="&DATE(2023,1,1),'Finance Tracker'!L:L,"<="&DATE(2023,12,31),'Finance Tracker'!F:F,"R-PV") +SUMIFS('Finance Tracker'!Q:Q,'Finance Tracker'!P:P,">="&DATE(2023,1,1),'Finance Tracker'!P:P,"<="&DATE(2023,12,31),'Finance Tracker'!F:F,"R-PV") +SUMIFS('Finance Tracker'!U:U,'Finance Tracker'!T:T,">="&DATE(2023,1,1),'Finance Tracker'!T:T,"<="&DATE(2023,12,31),'Finance Tracker'!F:F,"R-PV") +SUMIFS('Finance Tracker'!Y:Y,'Finance Tracker'!X:X,">="&DATE(2023,1,1),'Finance Tracker'!X:X,"<="&DATE(2023,12,31),'Finance Tracker'!F:F,"R-PV") +SUMIFS('Finance Tracker'!AC:AC,'Finance Tracker'!AB:AB,">="&DATE(2023,1,1),'Finance Tracker'!AB:AB,"<="&DATE(2023,12,31),'Finance Tracker'!F:F,"R-PV") +SUMIFS('Finance Tracker'!AG:AG,'Finance Tracker'!AF:AF,">="&DATE(2023,1,1),'Finance Tracker'!AF:AF,"<="&DATE(2023,12,31),'Finance Tracker'!F:F,"R-PV") -> 379240 | P37: =SUMIFS('Finance Tracker'!M:M,'Finance Tracker'!L:L,">="&DATE(2024,1,1),'Finance Tracker'!L:L,"<="&DATE(2024,12,31),'Finance Tracker'!F:F,"R-PV") +SUMIFS('Finance Tracker'!Q:Q,'Finance Tracker'!P:P,">="&DATE(2024,1,1),'Finance Tracker'!P:P,"<="&DATE(2024,12,31),'Finance Tracker'!F:F,"R-PV") +SUMIFS('Finance Tracker'!U:U,'Finance Tracker'!T:T,">="&DATE(2024,1,1),'Finance Tracker'!T:T,"<="&DATE(2024,12,31),'Finance Tracker'!F:F,"R-PV") +SUMIFS('Finance Tracker'!Y:Y,'Finance Tracker'!X:X,">="&DATE(2024,1,1),'Finance Tracker'!X:X,"<="&DATE(2024,12,31),'Finance Tracker'!F:F,"R-PV") +SUMIFS('Finance Tracker'!AC:AC,'Finance Tracker'!AB:AB,">="&DATE(2024,1,1),'Finance Tracker'!AB:AB,"<="&DATE(2024,12,31),'Finance Tracker'!F:F,"R-PV") +SUMIFS('Finance Tracker'!AG:AG,'Finance Tracker'!AF:AF,">="&DATE(2024,1,1),'Finance Tracker'!AF:AF,"<="&DATE(2024,12,31),'Finance Tracker'!F:F,"R-PV") -> 3897315.2 | Q37: =SUMIFS('Finance Tracker'!M:M,'Finance Tracker'!L:L,">="&DATE(2025,1,1),'Finance Tracker'!L:L,"<="&DATE(2025,12,31),'Finance Tracker'!F:F,"R-PV") +SUMIFS('Finance Tracker'!Q:Q,'Finance Tracker'!P:P,">="&DATE(2025,1,1),'Finance Tracker'!P:P,"<="&DATE(2025,12,31),'Finance Tracker'!F:F,"R-PV") +SUMIFS('Finance Tracker'!U:U,'Finance Tracker'!T:T,">="&DATE(2025,1,1),'Finance Tracker'!T:T,"<="&DATE(2025,12,31),'Finance Tracker'!F:F,"R-PV") +SUMIFS('Finance Tracker'!Y:Y,'Finance Tracker'!X:X,">="&DATE(2025,1,1),'Finance Tracker'!X:X,"<="&DATE(2025,12,31),'Finance Tracker'!F:F,"R-PV") +SUMIFS('Finance Tracker'!AC:AC,'Finance Tracker'!AB:AB,">="&DATE(2025,1,1),'Finance Tracker'!AB:AB,"<="&DATE(2025,12,31),'Finance Tracker'!F:F,"R-PV") +SUMIFS('Finance Tracker'!AG:AG,'Finance Tracker'!AF:AF,">="&DATE(2025,1,1),'Finance Tracker'!AF:AF,"<="&DATE(2025,12,31),'Finance Tracker'!F:F,"R-PV") -> 4525569.4 | R37: =SUMIFS('Finance Tracker'!M:M,'Finance Tracker'!L:L,">="&DATE(2026,1,1),'Finance Tracker'!L:L,"<="&DATE(2026,12,31),'Finance Tracker'!F:F,"R-PV") +SUMIFS('Finance Tracker'!Q:Q,'Finance Tracker'!P:P,">="&DATE(2026,1,1),'Finance Tracker'!P:P,"<="&DATE(2026,12,31),'Finance Tracker'!F:F,"R-PV") +SUMIFS('Finance Tracker'!U:U,'Finance Tracker'!T:T,">="&DATE(2026,1,1),'Finance Tracker'!T:T,"<="&DATE(2026,12,31),'Finance Tracker'!F:F,"R-PV") +SUMIFS('Finance Tracker'!Y:Y,'Finance Tracker'!X:X,">="&DATE(2026,1,1),'Finance Tracker'!X:X,"<="&DATE(2026,12,31),'Finance Tracker'!F:F,"R-PV") +SUMIFS('Finance Tracker'!AC:AC,'Finance Tracker'!AB:AB,">="&DATE(2026,1,1),'Finance Tracker'!AB:AB,"<="&DATE(2026,12,31),'Finance Tracker'!F:F,"R-PV") +SUMIFS('Finance Tracker'!AG:AG,'Finance Tracker'!AF:AF,">="&DATE(2026,1,1),'Finance Tracker'!AF:AF,"<="&DATE(2026,12,31),'Finance Tracker'!F:F,"R-PV") -> 0 | T37: =SUM(U37:X37) -> 8586827.6 | U37: =SUMIFS('Finance Tracker'!O:O,'Finance Tracker'!N:N,">="&DATE(2023,1,1),'Finance Tracker'!N:N,"<="&DATE(2023,12,31),'Finance Tracker'!F:F,"R-PV") +SUMIFS('Finance Tracker'!S:S,'Finance Tracker'!R:R,">="&DATE(2023,1,1),'Finance Tracker'!R:R,"<="&DATE(2023,12,31),'Finance Tracker'!F:F,"R-PV") +SUMIFS('Finance Tracker'!W:W,'Finance Tracker'!V:V,">="&DATE(2023,1,1),'Finance Tracker'!V:V,"<="&DATE(2023,12,31),'Finance Tracker'!F:F,"R-PV") +SUMIFS('Finance Tracker'!AA:AA,'Finance Tracker'!Z:Z,">="&DATE(2023,1,1),'Finance Tracker'!Z:Z,"<="&DATE(2023,12,31),'Finance Tracker'!F:F,"R-PV") +SUMIFS('Finance Tracker'!AD:AD,'Finance Tracker'!AE:AE,">="&DATE(2023,1,1),'Finance Tracker'!AE:AE,"<="&DATE(2023,12,31),'Finance Tracker'!F:F,"R-PV") +SUMIFS('Finance Tracker'!AI:AI,'Finance Tracker'!AH:AH,">="&DATE(2023,1,1),'Finance Tracker'!AH:AH,"<="&DATE(2023,12,31),'Finance Tracker'!F:F,"R-PV") -> 301640 | V37: =SUMIFS('Finance Tracker'!O:O,'Finance Tracker'!N:N,">="&DATE(2024,1,1),'Finance Tracker'!N:N,"<="&DATE(2024,12,31),'Finance Tracker'!F:F,"R-PV") +SUMIFS('Finance Tracker'!S:S,'Finance Tracker'!R:R,">="&DATE(2024,1,1),'Finance Tracker'!R:R,"<="&DATE(2024,12,31),'Finance Tracker'!F:F,"R-PV") +SUMIFS('Finance Tracker'!W:W,'Finance Tracker'!V:V,">="&DATE(2024,1,1),'Finance Tracker'!V:V,"<="&DATE(2024,12,31),'Finance Tracker'!F:F,"R-PV") +SUMIFS('Finance Tracker'!AA:AA,'Finance Tracker'!Z:Z,">="&DATE(2024,1,1),'Finance Tracker'!Z:Z,"<="&DATE(2024,12,31),'Finance Tracker'!F:F,"R-PV") +SUMIFS('Finance Tracker'!AD:AD,'Finance Tracker'!AE:AE,">="&DATE(2024,1,1),'Finance Tracker'!AE:AE,"<="&DATE(2024,12,31),'Finance Tracker'!F:F,"R-PV") +SUMIFS('Finance Tracker'!AI:AI,'Finance Tracker'!AH:AH,">="&DATE(2024,1,1),'Finance Tracker'!AH:AH,"<="&DATE(2024,12,31),'Finance Tracker'!F:F,"R-PV") -> 3691311.2 | W37: =SUMIFS('Finance Tracker'!O:O,'Finance Tracker'!N:N,">="&DATE(2025,1,1),'Finance Tracker'!N:N,"<="&DATE(2025,12,31),'Finance Tracker'!F:F,"R-PV") +SUMIFS('Finance Tracker'!S:S,'Finance Tracker'!R:R,">="&DATE(2025,1,1),'Finance Tracker'!R:R,"<="&DATE(2025,12,31),'Finance Tracker'!F:F,"R-PV") +SUMIFS('Finance Tracker'!W:W,'Finance Tracker'!V:V,">="&DATE(2025,1,1),'Finance Tracker'!V:V,"<="&DATE(2025,12,31),'Finance Tracker'!F:F,"R-PV") +SUMIFS('Finance Tracker'!AA:AA,'Finance Tracker'!Z:Z,">="&DATE(2025,1,1),'Finance Tracker'!Z:Z,"<="&DATE(2025,12,31),'Finance Tracker'!F:F,"R-PV") +SUMIFS('Finance Tracker'!AD:AD,'Finance Tracker'!AE:AE,">="&DATE(2025,1,1),'Finance Tracker'!AE:AE,"<="&DATE(2025,12,31),'Finance Tracker'!F:F,"R-PV") +SUMIFS('Finance Tracker'!AI:AI,'Finance Tracker'!AH:AH,">="&DATE(2025,1,1),'Finance Tracker'!AH:AH,"<="&DATE(2025,12,31),'Finance Tracker'!F:F,"R-PV") -> 4593876.4 | X37: =SUMIFS('Finance Tracker'!O:O,'Finance Tracker'!N:N,">="&DATE(2026,1,1),'Finance Tracker'!N:N,"<="&DATE(2026,12,31),'Finance Tracker'!F:F,"R-PV") +SUMIFS('Finance Tracker'!S:S,'Finance Tracker'!R:R,">="&DATE(2026,1,1),'Finance Tracker'!R:R,"<="&DATE(2026,12,31),'Finance Tracker'!F:F,"R-PV") +SUMIFS('Finance Tracker'!W:W,'Finance Tracker'!V:V,">="&DATE(2026,1,1),'Finance Tracker'!V:V,"<="&DATE(2026,12,31),'Finance Tracker'!F:F,"R-PV") +SUMIFS('Finance Tracker'!AA:AA,'Finance Tracker'!Z:Z,">="&DATE(2026,1,1),'Finance Tracker'!Z:Z,"<="&DATE(2026,12,31),'Finance Tracker'!F:F,"R-PV") +SUMIFS('Finance Tracker'!AE:AE,'Finance Tracker'!AE:AE,">="&DATE(2026,1,1),'Finance Tracker'!AD:AD,"<="&DATE(2026,12,31),'Finance Tracker'!F:F,"R-PV") +SUMIFS('Finance Tracker'!AI:AI,'Finance Tracker'!AH:AH,">="&DATE(2026,1,1),'Finance Tracker'!AH:AH,"<="&DATE(2026,12,31),'Finance Tracker'!F:F,"R-PV") -> 0 | Z37: =COUNTIF(Table1[Category],"R-PV") -> 313 | AA37: =COUNTIFS(Table1[Category],"R-PV",Table1[Closed Date],">="&DATE(2023,1,1),Table1[Closed Date],"<="&DATE(2023,12,31)) -> 23 | AB37: =COUNTIFS(Table1[Category],"R-PV",Table1[Closed Date],">="&DATE(2024,1,1),Table1[Closed Date],"<="&DATE(2024,12,31)) -> 143 | AC37: =COUNTIFS(Table1[Category],"R-PV",Table1[Closed Date],">="&DATE(2025,1,1),Table1[Closed Date],"<="&DATE(2025,12,31)) -> 147 | AD37: =COUNTIFS(Table1[Category],"R-PV",Table1[Closed Date],">="&DATE(2026,1,1),Table1[Closed Date],"<="&DATE(2026,12,31)) -> 0
A38: C&I (PV System) | B38: =SUMIFS(Table1[PV System Capacity (kWp)],Table1[Category],"*C&I*") -> 3718.01 | C38: =SUMIFS(Table1[PV System Capacity (kWp)],Table1[Category],"*C&I*",Table1[Closed Date],">="&DATE(2023,1,1),Table1[Closed Date],"<="&DATE(2023,12,31)) -> 428.695 | D38: =SUMIFS(Table1[PV System Capacity (kWp)],Table1[Category],"*C&I*",Table1[Closed Date],">="&DATE(2024,1,1),Table1[Closed Date],"<="&DATE(2024,12,31)) -> 2088.345 | E38: =SUMIFS(Table1[PV System Capacity (kWp)],Table1[Category],"*C&I*",Table1[Closed Date],">="&DATE(2025,1,1),Table1[Closed Date],"<="&DATE(2025,12,31)) -> 1200.97 | F38: =SUMIFS(Table1[PV System Capacity (kWp)],Table1[Category],"*C&I*",Table1[Closed Date],">="&DATE(2026,1,1),Table1[Closed Date],"<="&DATE(2026,12,31)) -> 0 | H38: =SUMIFS(Table1[Project Value (RM)],Table1[Category],"C&I-PV") -> 7185553.6 | I38: =SUMIFS(Table1[Project Value (RM)],Table1[Category],"C&I-PV",Table1[Closed Date],">="&DATE(2023,1,1),Table1[Closed Date],"<="&DATE(2023,12,31)) -> 521800 | J38: =SUMIFS(Table1[Project Value (RM)],Table1[Category],"C&I-PV",Table1[Closed Date],">="&DATE(2024,1,1),Table1[Closed Date],"<="&DATE(2024,12,31)) -> 4266680 | K38: =SUMIFS(Table1[Project Value (RM)],Table1[Category],"C&I-PV",Table1[Closed Date],">="&DATE(2025,1,1),Table1[Closed Date],"<="&DATE(2025,12,31)) -> 2397073.6 | L38: =SUMIFS(Table1[Project Value (RM)],Table1[Category],"C&I-PV",Table1[Closed Date],">="&DATE(2026,1,1),Table1[Closed Date],"<="&DATE(2026,12,31)) -> 0 | N38: =SUM(O38:R38) -> 6946746.4 | O38: =SUMIFS('Finance Tracker'!M:M,'Finance Tracker'!L:L,">="&DATE(2023,1,1),'Finance Tracker'!L:L,"<="&DATE(2023,12,31),'Finance Tracker'!F:F,"C&I-PV") +SUMIFS('Finance Tracker'!Q:Q,'Finance Tracker'!P:P,">="&DATE(2023,1,1),'Finance Tracker'!P:P,"<="&DATE(2023,12,31),'Finance Tracker'!F:F,"C&I-PV") +SUMIFS('Finance Tracker'!U:U,'Finance Tracker'!T:T,">="&DATE(2023,1,1),'Finance Tracker'!T:T,"<="&DATE(2023,12,31),'Finance Tracker'!F:F,"C&I-PV") +SUMIFS('Finance Tracker'!Y:Y,'Finance Tracker'!X:X,">="&DATE(2023,1,1),'Finance Tracker'!X:X,"<="&DATE(2023,12,31),'Finance Tracker'!F:F,"C&I-PV") +SUMIFS('Finance Tracker'!AC:AC,'Finance Tracker'!AB:AB,">="&DATE(2023,1,1),'Finance Tracker'!AB:AB,"<="&DATE(2023,12,31),'Finance Tracker'!F:F,"C&I-PV") +SUMIFS('Finance Tracker'!AG:AG,'Finance Tracker'!AF:AF,">="&DATE(2023,1,1),'Finance Tracker'!AF:AF,"<="&DATE(2023,12,31),'Finance Tracker'!F:F,"C&I-PV") -> 278820 | P38: =SUMIFS('Finance Tracker'!M:M,'Finance Tracker'!L:L,">="&DATE(2024,1,1),'Finance Tracker'!L:L,"<="&DATE(2024,12,31),'Finance Tracker'!F:F,"C&I-PV") +SUMIFS('Finance Tracker'!Q:Q,'Finance Tracker'!P:P,">="&DATE(2024,1,1),'Finance Tracker'!P:P,"<="&DATE(2024,12,31),'Finance Tracker'!F:F,"C&I-PV") +SUMIFS('Finance Tracker'!U:U,'Finance Tracker'!T:T,">="&DATE(2024,1,1),'Finance Tracker'!T:T,"<="&DATE(2024,12,31),'Finance Tracker'!F:F,"C&I-PV") +SUMIFS('Finance Tracker'!Y:Y,'Finance Tracker'!X:X,">="&DATE(2024,1,1),'Finance Tracker'!X:X,"<="&DATE(2024,12,31),'Finance Tracker'!F:F,"C&I-PV") +SUMIFS('Finance Tracker'!AC:AC,'Finance Tracker'!AB:AB,">="&DATE(2024,1,1),'Finance Tracker'!AB:AB,"<="&DATE(2024,12,31),'Finance Tracker'!F:F,"C&I-PV") +SUMIFS('Finance Tracker'!AG:AG,'Finance Tracker'!AF:AF,">="&DATE(2024,1,1),'Finance Tracker'!AF:AF,"<="&DATE(2024,12,31),'Finance Tracker'!F:F,"C&I-PV") -> 2643170 | Q38: =SUMIFS('Finance Tracker'!M:M,'Finance Tracker'!L:L,">="&DATE(2025,1,1),'Finance Tracker'!L:L,"<="&DATE(2025,12,31),'Finance Tracker'!F:F,"C&I-PV") +SUMIFS('Finance Tracker'!Q:Q,'Finance Tracker'!P:P,">="&DATE(2025,1,1),'Finance Tracker'!P:P,"<="&DATE(2025,12,31),'Finance Tracker'!F:F,"C&I-PV") +SUMIFS('Finance Tracker'!U:U,'Finance Tracker'!T:T,">="&DATE(2025,1,1),'Finance Tracker'!T:T,"<="&DATE(2025,12,31),'Finance Tracker'!F:F,"C&I-PV") +SUMIFS('Finance Tracker'!Y:Y,'Finance Tracker'!X:X,">="&DATE(2025,1,1),'Finance Tracker'!X:X,"<="&DATE(2025,12,31),'Finance Tracker'!F:F,"C&I-PV") +SUMIFS('Finance Tracker'!AC:AC,'Finance Tracker'!AB:AB,">="&DATE(2025,1,1),'Finance Tracker'!AB:AB,"<="&DATE(2025,12,31),'Finance Tracker'!F:F,"C&I-PV") +SUMIFS('Finance Tracker'!AG:AG,'Finance Tracker'!AF:AF,">="&DATE(2025,1,1),'Finance Tracker'!AF:AF,"<="&DATE(2025,12,31),'Finance Tracker'!F:F,"C&I-PV") -> 4024756.4 | R38: =SUMIFS('Finance Tracker'!M:M,'Finance Tracker'!L:L,">="&DATE(2026,1,1),'Finance Tracker'!L:L,"<="&DATE(2026,12,31),'Finance Tracker'!F:F,"C&I-PV") +SUMIFS('Finance Tracker'!Q:Q,'Finance Tracker'!P:P,">="&DATE(2026,1,1),'Finance Tracker'!P:P,"<="&DATE(2026,12,31),'Finance Tracker'!F:F,"C&I-PV") +SUMIFS('Finance Tracker'!U:U,'Finance Tracker'!T:T,">="&DATE(2026,1,1),'Finance Tracker'!T:T,"<="&DATE(2026,12,31),'Finance Tracker'!F:F,"C&I-PV") +SUMIFS('Finance Tracker'!Y:Y,'Finance Tracker'!X:X,">="&DATE(2026,1,1),'Finance Tracker'!X:X,"<="&DATE(2026,12,31),'Finance Tracker'!F:F,"C&I-PV") +SUMIFS('Finance Tracker'!AC:AC,'Finance Tracker'!AB:AB,">="&DATE(2026,1,1),'Finance Tracker'!AB:AB,"<="&DATE(2026,12,31),'Finance Tracker'!F:F,"C&I-PV") +SUMIFS('Finance Tracker'!AG:AG,'Finance Tracker'!AF:AF,">="&DATE(2026,1,1),'Finance Tracker'!AF:AF,"<="&DATE(2026,12,31),'Finance Tracker'!F:F,"C&I-PV") -> 0 | T38: =SUM(U38:X38) -> 5420201.4 | U38: =SUMIFS('Finance Tracker'!O:O,'Finance Tracker'!N:N,">="&DATE(2023,1,1),'Finance Tracker'!N:N,"<="&DATE(2023,12,31),'Finance Tracker'!F:F,"C&I-PV") +SUMIFS('Finance Tracker'!S:S,'Finance Tracker'!R:R,">="&DATE(2023,1,1),'Finance Tracker'!R:R,"<="&DATE(2023,12,31),'Finance Tracker'!F:F,"C&I-PV") +SUMIFS('Finance Tracker'!W:W,'Finance Tracker'!V:V,">="&DATE(2023,1,1),'Finance Tracker'!V:V,"<="&DATE(2023,12,31),'Finance Tracker'!F:F,"C&I-PV") +SUMIFS('Finance Tracker'!AA:AA,'Finance Tracker'!Z:Z,">="&DATE(2023,1,1),'Finance Tracker'!Z:Z,"<="&DATE(2023,12,31),'Finance Tracker'!F:F,"C&I-PV") +SUMIFS('Finance Tracker'!AD:AD,'Finance Tracker'!AE:AE,">="&DATE(2023,1,1),'Finance Tracker'!AE:AE,"<="&DATE(2023,12,31),'Finance Tracker'!F:F,"C&I-PV") +SUMIFS('Finance Tracker'!AI:AI,'Finance Tracker'!AH:AH,">="&DATE(2023,1,1),'Finance Tracker'!AH:AH,"<="&DATE(2023,12,31),'Finance Tracker'!F:F,"C&I-PV") -> 278820 | V38: =SUMIFS('Finance Tracker'!O:O,'Finance Tracker'!N:N,">="&DATE(2024,1,1),'Finance Tracker'!N:N,"<="&DATE(2024,12,31),'Finance Tracker'!F:F,"C&I-PV") +SUMIFS('Finance Tracker'!S:S,'Finance Tracker'!R:R,">="&DATE(2024,1,1),'Finance Tracker'!R:R,"<="&DATE(2024,12,31),'Finance Tracker'!F:F,"C&I-PV") +SUMIFS('Finance Tracker'!W:W,'Finance Tracker'!V:V,">="&DATE(2024,1,1),'Finance Tracker'!V:V,"<="&DATE(2024,12,31),'Finance Tracker'!F:F,"C&I-PV") +SUMIFS('Finance Tracker'!AA:AA,'Finance Tracker'!Z:Z,">="&DATE(2024,1,1),'Finance Tracker'!Z:Z,"<="&DATE(2024,12,31),'Finance Tracker'!F:F,"C&I-PV") +SUMIFS('Finance Tracker'!AD:AD,'Finance Tracker'!AE:AE,">="&DATE(2024,1,1),'Finance Tracker'!AE:AE,"<="&DATE(2024,12,31),'Finance Tracker'!F:F,"C&I-PV") +SUMIFS('Finance Tracker'!AI:AI,'Finance Tracker'!AH:AH,">="&DATE(2024,1,1),'Finance Tracker'!AH:AH,"<="&DATE(2024,12,31),'Finance Tracker'!F:F,"C&I-PV") -> 2422890 | W38: =SUMIFS('Finance Tracker'!O:O,'Finance Tracker'!N:N,">="&DATE(2025,1,1),'Finance Tracker'!N:N,"<="&DATE(2025,12,31),'Finance Tracker'!F:F,"C&I-PV") +SUMIFS('Finance Tracker'!S:S,'Finance Tracker'!R:R,">="&DATE(2025,1,1),'Finance Tracker'!R:R,"<="&DATE(2025,12,31),'Finance Tracker'!F:F,"C&I-PV") +SUMIFS('Finance Tracker'!W:W,'Finance Tracker'!V:V,">="&DATE(2025,1,1),'Finance Tracker'!V:V,"<="&DATE(2025,12,31),'Finance Tracker'!F:F,"C&I-PV") +SUMIFS('Finance Tracker'!AA:AA,'Finance Tracker'!Z:Z,">="&DATE(2025,1,1),'Finance Tracker'!Z:Z,"<="&DATE(2025,12,31),'Finance Tracker'!F:F,"C&I-PV") +SUMIFS('Finance Tracker'!AD:AD,'Finance Tracker'!AE:AE,">="&DATE(2025,1,1),'Finance Tracker'!AE:AE,"<="&DATE(2025,12,31),'Finance Tracker'!F:F,"C&I-PV") +SUMIFS('Finance Tracker'!AI:AI,'Finance Tracker'!AH:AH,">="&DATE(2025,1,1),'Finance Tracker'!AH:AH,"<="&DATE(2025,12,31),'Finance Tracker'!F:F,"C&I-PV") -> 2718491.4 | X38: =SUMIFS('Finance Tracker'!O:O,'Finance Tracker'!N:N,">="&DATE(2026,1,1),'Finance Tracker'!N:N,"<="&DATE(2026,12,31),'Finance Tracker'!F:F,"C&I-PV") +SUMIFS('Finance Tracker'!S:S,'Finance Tracker'!R:R,">="&DATE(2026,1,1),'Finance Tracker'!R:R,"<="&DATE(2026,12,31),'Finance Tracker'!F:F,"C&I-PV") +SUMIFS('Finance Tracker'!W:W,'Finance Tracker'!V:V,">="&DATE(2026,1,1),'Finance Tracker'!V:V,"<="&DATE(2026,12,31),'Finance Tracker'!F:F,"C&I-PV") +SUMIFS('Finance Tracker'!AA:AA,'Finance Tracker'!Z:Z,">="&DATE(2026,1,1),'Finance Tracker'!Z:Z,"<="&DATE(2026,12,31),'Finance Tracker'!F:F,"C&I-PV") +SUMIFS('Finance Tracker'!AD:AD,'Finance Tracker'!AE:AE,">="&DATE(2026,1,1),'Finance Tracker'!AE:AE,"<="&DATE(2026,12,31),'Finance Tracker'!F:F,"C&I-PV") +SUMIFS('Finance Tracker'!AI:AI,'Finance Tracker'!AH:AH,">="&DATE(2026,1,1),'Finance Tracker'!AH:AH,"<="&DATE(2026,12,31),'Finance Tracker'!F:F,"C&I-PV") -> 0 | Z38: =COUNTIF(Table1[Category],"C&I-PV") -> 33 | AA38: =COUNTIFS(Table1[Category],"C&I-PV",Table1[Closed Date],">="&DATE(2023,1,1),Table1[Closed Date],"<="&DATE(2023,12,31)) -> 3 | AB38: =COUNTIFS(Table1[Category],"C&I-PV",Table1[Closed Date],">="&DATE(2024,1,1),Table1[Closed Date],"<="&DATE(2024,12,31)) -> 18 | AC38: =COUNTIFS(Table1[Category],"C&I-PV",Table1[Closed Date],">="&DATE(2025,1,1),Table1[Closed Date],"<="&DATE(2025,12,31)) -> 12 | AD38: =COUNTIFS(Table1[Category],"C&I-PV",Table1[Closed Date],">="&DATE(2026,1,1),Table1[Closed Date],"<="&DATE(2026,12,31)) -> 0
A39: Residential BESS | B39: =SUMIFS(Table1[BESS Capacity],Table1[Category],"R-BESS") -> 287.4 | C39: =SUMIFS(Table1[BESS Capacity],Table1[Category],"R-BESS",Table1[Closed Date],">="&DATE(2023,1,1),Table1[Closed Date],"<="&DATE(2023,12,31)) -> 287.4 | D39: =SUMIFS(Table1[BESS Capacity],Table1[Category],"R-BESS",Table1[Closed Date],">="&DATE(2024,1,1),Table1[Closed Date],"<="&DATE(2024,12,31)) -> 0 | E39: =SUMIFS(Table1[BESS Capacity],Table1[Category],"R-BESS",Table1[Closed Date],">="&DATE(2025,1,1),Table1[Closed Date],"<="&DATE(2025,12,31)) -> 0 | F39: =SUMIFS(Table1[BESS Capacity],Table1[Category],"R-BESS",Table1[Closed Date],">="&DATE(2026,1,1),Table1[Closed Date],"<="&DATE(2026,12,31)) -> 0 | H39: =SUMIFS(Table1[Project Value (RM)],Table1[Category],"R-BESS") -> 720000 | I39: =SUMIFS(Table1[Project Value (RM)],Table1[Category],"R-BESS",Table1[Closed Date],">="&DATE(2023,1,1),Table1[Closed Date],"<="&DATE(2023,12,31)) -> 720000 | J39: =SUMIFS(Table1[Project Value (RM)],Table1[Category],"R-BESS",Table1[Closed Date],">="&DATE(2024,1,1),Table1[Closed Date],"<="&DATE(2024,12,31)) -> 0 | K39: =SUMIFS(Table1[Project Value (RM)],Table1[Category],"R-BESS",Table1[Closed Date],">="&DATE(2025,1,1),Table1[Closed Date],"<="&DATE(2025,12,31)) -> 0 | L39: =SUMIFS(Table1[Project Value (RM)],Table1[Category],"R-BESS",Table1[Closed Date],">="&DATE(2026,1,1),Table1[Closed Date],"<="&DATE(2026,12,31)) -> 0 | N39: =SUM(O39:R39) -> 720000 | O39: =SUMIFS('Finance Tracker'!M:M,'Finance Tracker'!L:L,">="&DATE(2023,1,1),'Finance Tracker'!L:L,"<="&DATE(2023,12,31),'Finance Tracker'!F:F,"R-BESS") +SUMIFS('Finance Tracker'!Q:Q,'Finance Tracker'!P:P,">="&DATE(2023,1,1),'Finance Tracker'!P:P,"<="&DATE(2023,12,31),'Finance Tracker'!F:F,"R-BESS") +SUMIFS('Finance Tracker'!U:U,'Finance Tracker'!T:T,">="&DATE(2023,1,1),'Finance Tracker'!T:T,"<="&DATE(2023,12,31),'Finance Tracker'!F:F,"R-BESS") +SUMIFS('Finance Tracker'!Y:Y,'Finance Tracker'!X:X,">="&DATE(2023,1,1),'Finance Tracker'!X:X,"<="&DATE(2023,12,31),'Finance Tracker'!F:F,"R-BESS") +SUMIFS('Finance Tracker'!AC:AC,'Finance Tracker'!AB:AB,">="&DATE(2023,1,1),'Finance Tracker'!AB:AB,"<="&DATE(2023,12,31),'Finance Tracker'!F:F,"R-BESS") +SUMIFS('Finance Tracker'!AG:AG,'Finance Tracker'!AF:AF,">="&DATE(2023,1,1),'Finance Tracker'!AF:AF,"<="&DATE(2023,12,31),'Finance Tracker'!F:F,"R-BESS") -> 432000 | P39: =SUMIFS('Finance Tracker'!M:M,'Finance Tracker'!L:L,">="&DATE(2024,1,1),'Finance Tracker'!L:L,"<="&DATE(2024,12,31),'Finance Tracker'!F:F,"R-BESS") +SUMIFS('Finance Tracker'!Q:Q,'Finance Tracker'!P:P,">="&DATE(2024,1,1),'Finance Tracker'!P:P,"<="&DATE(2024,12,31),'Finance Tracker'!F:F,"R-BESS") +SUMIFS('Finance Tracker'!U:U,'Finance Tracker'!T:T,">="&DATE(2024,1,1),'Finance Tracker'!T:T,"<="&DATE(2024,12,31),'Finance Tracker'!F:F,"R-BESS") +SUMIFS('Finance Tracker'!Y:Y,'Finance Tracker'!X:X,">="&DATE(2024,1,1),'Finance Tracker'!X:X,"<="&DATE(2024,12,31),'Finance Tracker'!F:F,"R-BESS") +SUMIFS('Finance Tracker'!AC:AC,'Finance Tracker'!AB:AB,">="&DATE(2024,1,1),'Finance Tracker'!AB:AB,"<="&DATE(2024,12,31),'Finance Tracker'!F:F,"R-BESS") +SUMIFS('Finance Tracker'!AG:AG,'Finance Tracker'!AF:AF,">="&DATE(2024,1,1),'Finance Tracker'!AF:AF,"<="&DATE(2024,12,31),'Finance Tracker'!F:F,"R-BESS") -> 288000 | Q39: =SUMIFS('Finance Tracker'!M:M,'Finance Tracker'!L:L,">="&DATE(2025,1,1),'Finance Tracker'!L:L,"<="&DATE(2025,12,31),'Finance Tracker'!F:F,"R-BESS") +SUMIFS('Finance Tracker'!Q:Q,'Finance Tracker'!P:P,">="&DATE(2025,1,1),'Finance Tracker'!P:P,"<="&DATE(2025,12,31),'Finance Tracker'!F:F,"R-BESS") +SUMIFS('Finance Tracker'!U:U,'Finance Tracker'!T:T,">="&DATE(2025,1,1),'Finance Tracker'!T:T,"<="&DATE(2025,12,31),'Finance Tracker'!F:F,"R-BESS") +SUMIFS('Finance Tracker'!Y:Y,'Finance Tracker'!X:X,">="&DATE(2025,1,1),'Finance Tracker'!X:X,"<="&DATE(2025,12,31),'Finance Tracker'!F:F,"R-BESS") +SUMIFS('Finance Tracker'!AC:AC,'Finance Tracker'!AB:AB,">="&DATE(2025,1,1),'Finance Tracker'!AB:AB,"<="&DATE(2025,12,31),'Finance Tracker'!F:F,"R-BESS") +SUMIFS('Finance Tracker'!AG:AG,'Finance Tracker'!AF:AF,">="&DATE(2025,1,1),'Finance Tracker'!AF:AF,"<="&DATE(2025,12,31),'Finance Tracker'!F:F,"R-BESS") -> 0 | R39: =SUMIFS('Finance Tracker'!M:M,'Finance Tracker'!L:L,">="&DATE(2026,1,1),'Finance Tracker'!L:L,"<="&DATE(2026,12,31),'Finance Tracker'!F:F,"R-BESS") +SUMIFS('Finance Tracker'!Q:Q,'Finance Tracker'!P:P,">="&DATE(2026,1,1),'Finance Tracker'!P:P,"<="&DATE(2026,12,31),'Finance Tracker'!F:F,"R-BESS") +SUMIFS('Finance Tracker'!U:U,'Finance Tracker'!T:T,">="&DATE(2026,1,1),'Finance Tracker'!T:T,"<="&DATE(2026,12,31),'Finance Tracker'!F:F,"R-BESS") +SUMIFS('Finance Tracker'!Y:Y,'Finance Tracker'!X:X,">="&DATE(2026,1,1),'Finance Tracker'!X:X,"<="&DATE(2026,12,31),'Finance Tracker'!F:F,"R-BESS") +SUMIFS('Finance Tracker'!AC:AC,'Finance Tracker'!AB:AB,">="&DATE(2026,1,1),'Finance Tracker'!AB:AB,"<="&DATE(2026,12,31),'Finance Tracker'!F:F,"R-BESS") +SUMIFS('Finance Tracker'!AG:AG,'Finance Tracker'!AF:AF,">="&DATE(2026,1,1),'Finance Tracker'!AF:AF,"<="&DATE(2026,12,31),'Finance Tracker'!F:F,"R-BESS") -> 0 | T39: =SUM(U39:X39) -> 720000 | U39: =SUMIFS('Finance Tracker'!O:O,'Finance Tracker'!N:N,">="&DATE(2023,1,1),'Finance Tracker'!N:N,"<="&DATE(2023,12,31),'Finance Tracker'!F:F,"R-BESS") +SUMIFS('Finance Tracker'!S:S,'Finance Tracker'!R:R,">="&DATE(2023,1,1),'Finance Tracker'!R:R,"<="&DATE(2023,12,31),'Finance Tracker'!F:F,"R-BESS") +SUMIFS('Finance Tracker'!W:W,'Finance Tracker'!V:V,">="&DATE(2023,1,1),'Finance Tracker'!V:V,"<="&DATE(2023,12,31),'Finance Tracker'!F:F,"R-BESS") +SUMIFS('Finance Tracker'!AA:AA,'Finance Tracker'!Z:Z,">="&DATE(2023,1,1),'Finance Tracker'!Z:Z,"<="&DATE(2023,12,31),'Finance Tracker'!F:F,"R-BESS") +SUMIFS('Finance Tracker'!AD:AD,'Finance Tracker'!AE:AE,">="&DATE(2023,1,1),'Finance Tracker'!AE:AE,"<="&DATE(2023,12,31),'Finance Tracker'!F:F,"R-BESS") +SUMIFS('Finance Tracker'!AI:AI,'Finance Tracker'!AH:AH,">="&DATE(2023,1,1),'Finance Tracker'!AH:AH,"<="&DATE(2023,12,31),'Finance Tracker'!F:F,"R-BESS") -> 432000 | V39: =SUMIFS('Finance Tracker'!O:O,'Finance Tracker'!N:N,">="&DATE(2024,1,1),'Finance Tracker'!N:N,"<="&DATE(2024,12,31),'Finance Tracker'!F:F,"R-BESS") +SUMIFS('Finance Tracker'!S:S,'Finance Tracker'!R:R,">="&DATE(2024,1,1),'Finance Tracker'!R:R,"<="&DATE(2024,12,31),'Finance Tracker'!F:F,"R-BESS") +SUMIFS('Finance Tracker'!W:W,'Finance Tracker'!V:V,">="&DATE(2024,1,1),'Finance Tracker'!V:V,"<="&DATE(2024,12,31),'Finance Tracker'!F:F,"R-BESS") +SUMIFS('Finance Tracker'!AA:AA,'Finance Tracker'!Z:Z,">="&DATE(2024,1,1),'Finance Tracker'!Z:Z,"<="&DATE(2024,12,31),'Finance Tracker'!F:F,"R-BESS") +SUMIFS('Finance Tracker'!AD:AD,'Finance Tracker'!AE:AE,">="&DATE(2024,1,1),'Finance Tracker'!AE:AE,"<="&DATE(2024,12,31),'Finance Tracker'!F:F,"R-BESS") +SUMIFS('Finance Tracker'!AI:AI,'Finance Tracker'!AH:AH,">="&DATE(2024,1,1),'Finance Tracker'!AH:AH,"<="&DATE(2024,12,31),'Finance Tracker'!F:F,"R-BESS") -> 288000 | W39: =SUMIFS('Finance Tracker'!O:O,'Finance Tracker'!N:N,">="&DATE(2025,1,1),'Finance Tracker'!N:N,"<="&DATE(2025,12,31),'Finance Tracker'!F:F,"R-BESS") +SUMIFS('Finance Tracker'!S:S,'Finance Tracker'!R:R,">="&DATE(2025,1,1),'Finance Tracker'!R:R,"<="&DATE(2025,12,31),'Finance Tracker'!F:F,"R-BESS") +SUMIFS('Finance Tracker'!W:W,'Finance Tracker'!V:V,">="&DATE(2025,1,1),'Finance Tracker'!V:V,"<="&DATE(2025,12,31),'Finance Tracker'!F:F,"R-BESS") +SUMIFS('Finance Tracker'!AA:AA,'Finance Tracker'!Z:Z,">="&DATE(2025,1,1),'Finance Tracker'!Z:Z,"<="&DATE(2025,12,31),'Finance Tracker'!F:F,"R-BESS") +SUMIFS('Finance Tracker'!AD:AD,'Finance Tracker'!AE:AE,">="&DATE(2025,1,1),'Finance Tracker'!AE:AE,"<="&DATE(2025,12,31),'Finance Tracker'!F:F,"R-BESS") +SUMIFS('Finance Tracker'!AI:AI,'Finance Tracker'!AH:AH,">="&DATE(2025,1,1),'Finance Tracker'!AH:AH,"<="&DATE(2025,12,31),'Finance Tracker'!F:F,"R-BESS") -> 0 | X39: =SUMIFS('Finance Tracker'!O:O,'Finance Tracker'!N:N,">="&DATE(2026,1,1),'Finance Tracker'!N:N,"<="&DATE(2026,12,31),'Finance Tracker'!F:F,"R-BESS") +SUMIFS('Finance Tracker'!S:S,'Finance Tracker'!R:R,">="&DATE(2026,1,1),'Finance Tracker'!R:R,"<="&DATE(2026,12,31),'Finance Tracker'!F:F,"R-BESS") +SUMIFS('Finance Tracker'!W:W,'Finance Tracker'!V:V,">="&DATE(2026,1,1),'Finance Tracker'!V:V,"<="&DATE(2026,12,31),'Finance Tracker'!F:F,"R-BESS") +SUMIFS('Finance Tracker'!AA:AA,'Finance Tracker'!Z:Z,">="&DATE(2026,1,1),'Finance Tracker'!Z:Z,"<="&DATE(2026,12,31),'Finance Tracker'!F:F,"R-BESS") +SUMIFS('Finance Tracker'!AD:AD,'Finance Tracker'!AE:AE,">="&DATE(2026,1,1),'Finance Tracker'!AE:AE,"<="&DATE(2026,12,31),'Finance Tracker'!F:F,"R-BESS") +SUMIFS('Finance Tracker'!AI:AI,'Finance Tracker'!AH:AH,">="&DATE(2026,1,1),'Finance Tracker'!AH:AH,"<="&DATE(2026,12,31),'Finance Tracker'!F:F,"R-BESS") -> 0 | Z39: =COUNTIF(Table1[Category],"R-BESS") -> 1 | AA39: =COUNTIFS(Table1[Category],"R-BESS",Table1[Closed Date],">="&DATE(2023,1,1),Table1[Closed Date],"<="&DATE(2023,12,31)) -> 1 | AB39: =COUNTIFS(Table1[Category],"R-BESS",Table1[Closed Date],">="&DATE(2024,1,1),Table1[Closed Date],"<="&DATE(2024,12,31)) -> 0 | AC39: =COUNTIFS(Table1[Category],"R-BESS",Table1[Closed Date],">="&DATE(2025,1,1),Table1[Closed Date],"<="&DATE(2025,12,31)) -> 0 | AD39: =COUNTIFS(Table1[Category],"R-BESS",Table1[Closed Date],">="&DATE(2026,1,1),Table1[Closed Date],"<="&DATE(2026,12,31)) -> 0
A40: C&I BESS | B40: =SUMIFS(Table1[BESS Capacity],Table1[Category],"C&I-BESS") -> 0 | C40: =SUMIFS(Table1[BESS Capacity],Table1[Category],"C&I-BESS",Table1[Closed Date],">="&DATE(2023,1,1),Table1[Closed Date],"<="&DATE(2023,12,31)) -> 0 | D40: =SUMIFS(Table1[BESS Capacity],Table1[Category],"C&I-BESS",Table1[Closed Date],">="&DATE(2024,1,1),Table1[Closed Date],"<="&DATE(2024,12,31)) -> 0 | E40: =SUMIFS(Table1[BESS Capacity],Table1[Category],"C&I-BESS",Table1[Closed Date],">="&DATE(2025,1,1),Table1[Closed Date],"<="&DATE(2025,12,31)) -> 0 | F40: =SUMIFS(Table1[BESS Capacity],Table1[Category],"C&I-BESS",Table1[Closed Date],">="&DATE(2026,1,1),Table1[Closed Date],"<="&DATE(2026,12,31)) -> 0 | H40: =SUMIFS(Table1[Project Value (RM)],Table1[Category],"C&I-BESS") -> 0 | I40: =SUMIFS(Table1[Project Value (RM)],Table1[Category],"C&I-BESS",Table1[Closed Date],">="&DATE(2023,1,1),Table1[Closed Date],"<="&DATE(2023,12,31)) -> 0 | J40: =SUMIFS(Table1[Project Value (RM)],Table1[Category],"C&I-BESS",Table1[Closed Date],">="&DATE(2024,1,1),Table1[Closed Date],"<="&DATE(2024,12,31)) -> 0 | K40: =SUMIFS(Table1[Project Value (RM)],Table1[Category],"C&I-BESS",Table1[Closed Date],">="&DATE(2025,1,1),Table1[Closed Date],"<="&DATE(2025,12,31)) -> 0 | L40: =SUMIFS(Table1[Project Value (RM)],Table1[Category],"C&I-BESS",Table1[Closed Date],">="&DATE(2026,1,1),Table1[Closed Date],"<="&DATE(2026,12,31)) -> 0 | N40: =SUM(O40:R40) -> 0 | O40: =SUMIFS('Finance Tracker'!M:M,'Finance Tracker'!L:L,">="&DATE(2023,1,1),'Finance Tracker'!L:L,"<="&DATE(2023,12,31),'Finance Tracker'!F:F,"C&I-BESS") +SUMIFS('Finance Tracker'!Q:Q,'Finance Tracker'!P:P,">="&DATE(2023,1,1),'Finance Tracker'!P:P,"<="&DATE(2023,12,31),'Finance Tracker'!F:F,"C&I-BESS") +SUMIFS('Finance Tracker'!U:U,'Finance Tracker'!T:T,">="&DATE(2023,1,1),'Finance Tracker'!T:T,"<="&DATE(2023,12,31),'Finance Tracker'!F:F,"C&I-BESS") +SUMIFS('Finance Tracker'!Y:Y,'Finance Tracker'!X:X,">="&DATE(2023,1,1),'Finance Tracker'!X:X,"<="&DATE(2023,12,31),'Finance Tracker'!F:F,"C&I-BESS") +SUMIFS('Finance Tracker'!AC:AC,'Finance Tracker'!AB:AB,">="&DATE(2023,1,1),'Finance Tracker'!AB:AB,"<="&DATE(2023,12,31),'Finance Tracker'!F:F,"C&I-BESS") +SUMIFS('Finance Tracker'!AG:AG,'Finance Tracker'!AF:AF,">="&DATE(2023,1,1),'Finance Tracker'!AF:AF,"<="&DATE(2023,12,31),'Finance Tracker'!F:F,"C&I-BESS") -> 0 | P40: =SUMIFS('Finance Tracker'!M:M,'Finance Tracker'!L:L,">="&DATE(2024,1,1),'Finance Tracker'!L:L,"<="&DATE(2024,12,31),'Finance Tracker'!F:F,"C&I-BESS") +SUMIFS('Finance Tracker'!Q:Q,'Finance Tracker'!P:P,">="&DATE(2024,1,1),'Finance Tracker'!P:P,"<="&DATE(2024,12,31),'Finance Tracker'!F:F,"C&I-BESS") +SUMIFS('Finance Tracker'!U:U,'Finance Tracker'!T:T,">="&DATE(2024,1,1),'Finance Tracker'!T:T,"<="&DATE(2024,12,31),'Finance Tracker'!F:F,"C&I-BESS") +SUMIFS('Finance Tracker'!Y:Y,'Finance Tracker'!X:X,">="&DATE(2024,1,1),'Finance Tracker'!X:X,"<="&DATE(2024,12,31),'Finance Tracker'!F:F,"C&I-BESS") +SUMIFS('Finance Tracker'!AC:AC,'Finance Tracker'!AB:AB,">="&DATE(2024,1,1),'Finance Tracker'!AB:AB,"<="&DATE(2024,12,31),'Finance Tracker'!F:F,"C&I-BESS") +SUMIFS('Finance Tracker'!AG:AG,'Finance Tracker'!AF:AF,">="&DATE(2024,1,1),'Finance Tracker'!AF:AF,"<="&DATE(2024,12,31),'Finance Tracker'!F:F,"C&I-BESS") -> 0 | Q40: =SUMIFS('Finance Tracker'!M:M,'Finance Tracker'!L:L,">="&DATE(2025,1,1),'Finance Tracker'!L:L,"<="&DATE(2025,12,31),'Finance Tracker'!F:F,"C&I-BESS") +SUMIFS('Finance Tracker'!Q:Q,'Finance Tracker'!P:P,">="&DATE(2025,1,1),'Finance Tracker'!P:P,"<="&DATE(2025,12,31),'Finance Tracker'!F:F,"C&I-BESS") +SUMIFS('Finance Tracker'!U:U,'Finance Tracker'!T:T,">="&DATE(2025,1,1),'Finance Tracker'!T:T,"<="&DATE(2025,12,31),'Finance Tracker'!F:F,"C&I-BESS") +SUMIFS('Finance Tracker'!Y:Y,'Finance Tracker'!X:X,">="&DATE(2025,1,1),'Finance Tracker'!X:X,"<="&DATE(2025,12,31),'Finance Tracker'!F:F,"C&I-BESS") +SUMIFS('Finance Tracker'!AC:AC,'Finance Tracker'!AB:AB,">="&DATE(2025,1,1),'Finance Tracker'!AB:AB,"<="&DATE(2025,12,31),'Finance Tracker'!F:F,"C&I-BESS") +SUMIFS('Finance Tracker'!AG:AG,'Finance Tracker'!AF:AF,">="&DATE(2025,1,1),'Finance Tracker'!AF:AF,"<="&DATE(2025,12,31),'Finance Tracker'!F:F,"C&I-BESS") -> 0 | R40: =SUMIFS('Finance Tracker'!M:M,'Finance Tracker'!L:L,">="&DATE(2026,1,1),'Finance Tracker'!L:L,"<="&DATE(2026,12,31),'Finance Tracker'!F:F,"C&I-BESS") +SUMIFS('Finance Tracker'!Q:Q,'Finance Tracker'!P:P,">="&DATE(2026,1,1),'Finance Tracker'!P:P,"<="&DATE(2026,12,31),'Finance Tracker'!F:F,"C&I-BESS") +SUMIFS('Finance Tracker'!U:U,'Finance Tracker'!T:T,">="&DATE(2026,1,1),'Finance Tracker'!T:T,"<="&DATE(2026,12,31),'Finance Tracker'!F:F,"C&I-BESS") +SUMIFS('Finance Tracker'!Y:Y,'Finance Tracker'!X:X,">="&DATE(2026,1,1),'Finance Tracker'!X:X,"<="&DATE(2026,12,31),'Finance Tracker'!F:F,"C&I-BESS") +SUMIFS('Finance Tracker'!AC:AC,'Finance Tracker'!AB:AB,">="&DATE(2026,1,1),'Finance Tracker'!AB:AB,"<="&DATE(2026,12,31),'Finance Tracker'!F:F,"C&I-BESS") +SUMIFS('Finance Tracker'!AG:AG,'Finance Tracker'!AF:AF,">="&DATE(2026,1,1),'Finance Tracker'!AF:AF,"<="&DATE(2026,12,31),'Finance Tracker'!F:F,"C&I-BESS") -> 0 | T40: =SUM(U40:X40) -> 0 | U40: =SUMIFS('Finance Tracker'!O:O,'Finance Tracker'!N:N,">="&DATE(2023,1,1),'Finance Tracker'!N:N,"<="&DATE(2023,12,31),'Finance Tracker'!F:F,"C&I-BESS") +SUMIFS('Finance Tracker'!S:S,'Finance Tracker'!R:R,">="&DATE(2023,1,1),'Finance Tracker'!R:R,"<="&DATE(2023,12,31),'Finance Tracker'!F:F,"C&I-BESS") +SUMIFS('Finance Tracker'!W:W,'Finance Tracker'!V:V,">="&DATE(2023,1,1),'Finance Tracker'!V:V,"<="&DATE(2023,12,31),'Finance Tracker'!F:F,"C&I-BESS") +SUMIFS('Finance Tracker'!AA:AA,'Finance Tracker'!Z:Z,">="&DATE(2023,1,1),'Finance Tracker'!Z:Z,"<="&DATE(2023,12,31),'Finance Tracker'!F:F,"C&I-BESS") +SUMIFS('Finance Tracker'!AD:AD,'Finance Tracker'!AE:AE,">="&DATE(2023,1,1),'Finance Tracker'!AE:AE,"<="&DATE(2023,12,31),'Finance Tracker'!F:F,"C&I-BESS") +SUMIFS('Finance Tracker'!AI:AI,'Finance Tracker'!AH:AH,">="&DATE(2023,1,1),'Finance Tracker'!AH:AH,"<="&DATE(2023,12,31),'Finance Tracker'!F:F,"C&I-BESS") -> 0 | V40: =SUMIFS('Finance Tracker'!O:O,'Finance Tracker'!N:N,">="&DATE(2024,1,1),'Finance Tracker'!N:N,"<="&DATE(2024,12,31),'Finance Tracker'!F:F,"C&I-BESS") +SUMIFS('Finance Tracker'!S:S,'Finance Tracker'!R:R,">="&DATE(2024,1,1),'Finance Tracker'!R:R,"<="&DATE(2024,12,31),'Finance Tracker'!F:F,"C&I-BESS") +SUMIFS('Finance Tracker'!W:W,'Finance Tracker'!V:V,">="&DATE(2024,1,1),'Finance Tracker'!V:V,"<="&DATE(2024,12,31),'Finance Tracker'!F:F,"C&I-BESS") +SUMIFS('Finance Tracker'!AA:AA,'Finance Tracker'!Z:Z,">="&DATE(2024,1,1),'Finance Tracker'!Z:Z,"<="&DATE(2024,12,31),'Finance Tracker'!F:F,"C&I-BESS") +SUMIFS('Finance Tracker'!AD:AD,'Finance Tracker'!AE:AE,">="&DATE(2024,1,1),'Finance Tracker'!AE:AE,"<="&DATE(2024,12,31),'Finance Tracker'!F:F,"C&I-BESS") +SUMIFS('Finance Tracker'!AI:AI,'Finance Tracker'!AH:AH,">="&DATE(2024,1,1),'Finance Tracker'!AH:AH,"<="&DATE(2024,12,31),'Finance Tracker'!F:F,"C&I-BESS") -> 0 | W40: =SUMIFS('Finance Tracker'!O:O,'Finance Tracker'!N:N,">="&DATE(2025,1,1),'Finance Tracker'!N:N,"<="&DATE(2025,12,31),'Finance Tracker'!F:F,"C&I-BESS") +SUMIFS('Finance Tracker'!S:S,'Finance Tracker'!R:R,">="&DATE(2025,1,1),'Finance Tracker'!R:R,"<="&DATE(2025,12,31),'Finance Tracker'!F:F,"C&I-BESS") +SUMIFS('Finance Tracker'!W:W,'Finance Tracker'!V:V,">="&DATE(2025,1,1),'Finance Tracker'!V:V,"<="&DATE(2025,12,31),'Finance Tracker'!F:F,"C&I-BESS") +SUMIFS('Finance Tracker'!AA:AA,'Finance Tracker'!Z:Z,">="&DATE(2025,1,1),'Finance Tracker'!Z:Z,"<="&DATE(2025,12,31),'Finance Tracker'!F:F,"C&I-BESS") +SUMIFS('Finance Tracker'!AD:AD,'Finance Tracker'!AE:AE,">="&DATE(2025,1,1),'Finance Tracker'!AE:AE,"<="&DATE(2025,12,31),'Finance Tracker'!F:F,"C&I-BESS") +SUMIFS('Finance Tracker'!AI:AI,'Finance Tracker'!AH:AH,">="&DATE(2025,1,1),'Finance Tracker'!AH:AH,"<="&DATE(2025,12,31),'Finance Tracker'!F:F,"C&I-BESS") -> 0 | X40: =SUMIFS('Finance Tracker'!O:O,'Finance Tracker'!N:N,">="&DATE(2026,1,1),'Finance Tracker'!N:N,"<="&DATE(2026,12,31),'Finance Tracker'!F:F,"C&I-BESS") +SUMIFS('Finance Tracker'!S:S,'Finance Tracker'!R:R,">="&DATE(2026,1,1),'Finance Tracker'!R:R,"<="&DATE(2026,12,31),'Finance Tracker'!F:F,"C&I-BESS") +SUMIFS('Finance Tracker'!W:W,'Finance Tracker'!V:V,">="&DATE(2026,1,1),'Finance Tracker'!V:V,"<="&DATE(2026,12,31),'Finance Tracker'!F:F,"C&I-BESS") +SUMIFS('Finance Tracker'!AA:AA,'Finance Tracker'!Z:Z,">="&DATE(2026,1,1),'Finance Tracker'!Z:Z,"<="&DATE(2026,12,31),'Finance Tracker'!F:F,"C&I-BESS") +SUMIFS('Finance Tracker'!AD:AD,'Finance Tracker'!AE:AE,">="&DATE(2026,1,1),'Finance Tracker'!AE:AE,"<="&DATE(2026,12,31),'Finance Tracker'!F:F,"C&I-BESS") +SUMIFS('Finance Tracker'!AI:AI,'Finance Tracker'!AH:AH,">="&DATE(2026,1,1),'Finance Tracker'!AH:AH,"<="&DATE(2026,12,31),'Finance Tracker'!F:F,"C&I-BESS") -> 0 | Z40: =COUNTIF(Table1[Category],"C&I-BESS") -> 0 | AA40: =COUNTIFS(Table1[Category],"C&I-BESS",Table1[Closed Date],">="&DATE(2023,1,1),Table1[Closed Date],"<="&DATE(2023,12,31)) -> 0 | AB40: =COUNTIFS(Table1[Category],"C&I-BESS",Table1[Closed Date],">="&DATE(2024,1,1),Table1[Closed Date],"<="&DATE(2024,12,31)) -> 0 | AC40: =COUNTIFS(Table1[Category],"C&I-BESS",Table1[Closed Date],">="&DATE(2025,1,1),Table1[Closed Date],"<="&DATE(2025,12,31)) -> 0 | AD40: =COUNTIFS(Table1[Scheme],"C&I-BESS",Table1[Sales PIC],">="&DATE(2026,1,1),Table1[Sales PIC],"<="&DATE(2026,12,31)) -> 0
A41: EV Chargers | B41: =SUMIFS(Table1[EV Charger Capacity],Table1[Category],"EV Charger") -> 1786 | C41: =SUMIFS(Table1[EV Charger Capacity],Table1[Category],"EV Charger",Table1[Closed Date],">="&DATE(2023,1,1),Table1[Closed Date],"<="&DATE(2023,12,31)) -> 100 | D41: =SUMIFS(Table1[EV Charger Capacity],Table1[Category],"EV Charger",Table1[Closed Date],">="&DATE(2024,1,1),Table1[Closed Date],"<="&DATE(2024,12,31)) -> 789 | E41: =SUMIFS(Table1[EV Charger Capacity],Table1[Category],"EV Charger",Table1[Closed Date],">="&DATE(2025,1,1),Table1[Closed Date],"<="&DATE(2025,12,31)) -> 897 | F41: =SUMIFS(Table1[EV Charger Capacity],Table1[Category],"EV Charger",Table1[Closed Date],">="&DATE(2026,1,1),Table1[Closed Date],"<="&DATE(2026,12,31)) -> 0 | H41: =SUMIFS(Table1[Project Value (RM)],Table1[Category],"EV Charger") -> 1430963 | I41: =SUMIFS(Table1[Project Value (RM)],Table1[Category],"EV Charger",Table1[Closed Date],">="&DATE(2023,1,1),Table1[Closed Date],"<="&DATE(2023,12,31)) -> 93380 | J41: =SUMIFS(Table1[Project Value (RM)],Table1[Category],"EV Charger",Table1[Closed Date],">="&DATE(2024,1,1),Table1[Closed Date],"<="&DATE(2024,12,31)) -> 355363 | K41: =SUMIFS(Table1[Project Value (RM)],Table1[Category],"EV Charger",Table1[Closed Date],">="&DATE(2025,1,1),Table1[Closed Date],"<="&DATE(2025,12,31)) -> 982220 | L41: =SUMIFS(Table1[Project Value (RM)],Table1[Category],"EV Charger",Table1[Closed Date],">="&DATE(2026,1,1),Table1[Closed Date],"<="&DATE(2026,12,31)) -> 0 | N41: =SUM(O41:R41) -> 957823 | O41: =SUMIFS('Finance Tracker'!M:M,'Finance Tracker'!L:L,">="&DATE(2023,1,1),'Finance Tracker'!L:L,"<="&DATE(2023,12,31),'Finance Tracker'!F:F,"EV Charger") +SUMIFS('Finance Tracker'!Q:Q,'Finance Tracker'!P:P,">="&DATE(2023,1,1),'Finance Tracker'!P:P,"<="&DATE(2023,12,31),'Finance Tracker'!F:F,"EV Charger") +SUMIFS('Finance Tracker'!U:U,'Finance Tracker'!T:T,">="&DATE(2023,1,1),'Finance Tracker'!T:T,"<="&DATE(2023,12,31),'Finance Tracker'!F:F,"EV Charger") +SUMIFS('Finance Tracker'!Y:Y,'Finance Tracker'!X:X,">="&DATE(2023,1,1),'Finance Tracker'!X:X,"<="&DATE(2023,12,31),'Finance Tracker'!F:F,"EV Charger") +SUMIFS('Finance Tracker'!AC:AC,'Finance Tracker'!AB:AB,">="&DATE(2023,1,1),'Finance Tracker'!AB:AB,"<="&DATE(2023,12,31),'Finance Tracker'!F:F,"EV Charger") +SUMIFS('Finance Tracker'!AG:AG,'Finance Tracker'!AF:AF,">="&DATE(2023,1,1),'Finance Tracker'!AF:AF,"<="&DATE(2023,12,31),'Finance Tracker'!F:F,"EV Charger") -> 46690 | P41: =SUMIFS('Finance Tracker'!M:M,'Finance Tracker'!L:L,">="&DATE(2024,1,1),'Finance Tracker'!L:L,"<="&DATE(2024,12,31),'Finance Tracker'!F:F,"EV Charger") +SUMIFS('Finance Tracker'!Q:Q,'Finance Tracker'!P:P,">="&DATE(2024,1,1),'Finance Tracker'!P:P,"<="&DATE(2024,12,31),'Finance Tracker'!F:F,"EV Charger") +SUMIFS('Finance Tracker'!U:U,'Finance Tracker'!T:T,">="&DATE(2024,1,1),'Finance Tracker'!T:T,"<="&DATE(2024,12,31),'Finance Tracker'!F:F,"EV Charger") +SUMIFS('Finance Tracker'!Y:Y,'Finance Tracker'!X:X,">="&DATE(2024,1,1),'Finance Tracker'!X:X,"<="&DATE(2024,12,31),'Finance Tracker'!F:F,"EV Charger") +SUMIFS('Finance Tracker'!AC:AC,'Finance Tracker'!AB:AB,">="&DATE(2024,1,1),'Finance Tracker'!AB:AB,"<="&DATE(2024,12,31),'Finance Tracker'!F:F,"EV Charger") +SUMIFS('Finance Tracker'!AG:AG,'Finance Tracker'!AF:AF,">="&DATE(2024,1,1),'Finance Tracker'!AF:AF,"<="&DATE(2024,12,31),'Finance Tracker'!F:F,"EV Charger") -> 342903 | Q41: =SUMIFS('Finance Tracker'!M:M,'Finance Tracker'!L:L,">="&DATE(2025,1,1),'Finance Tracker'!L:L,"<="&DATE(2025,12,31),'Finance Tracker'!F:F,"EV Charger") +SUMIFS('Finance Tracker'!Q:Q,'Finance Tracker'!P:P,">="&DATE(2025,1,1),'Finance Tracker'!P:P,"<="&DATE(2025,12,31),'Finance Tracker'!F:F,"EV Charger") +SUMIFS('Finance Tracker'!U:U,'Finance Tracker'!T:T,">="&DATE(2025,1,1),'Finance Tracker'!T:T,"<="&DATE(2025,12,31),'Finance Tracker'!F:F,"EV Charger") +SUMIFS('Finance Tracker'!Y:Y,'Finance Tracker'!X:X,">="&DATE(2025,1,1),'Finance Tracker'!X:X,"<="&DATE(2025,12,31),'Finance Tracker'!F:F,"EV Charger") +SUMIFS('Finance Tracker'!AC:AC,'Finance Tracker'!AB:AB,">="&DATE(2025,1,1),'Finance Tracker'!AB:AB,"<="&DATE(2025,12,31),'Finance Tracker'!F:F,"EV Charger") +SUMIFS('Finance Tracker'!AG:AG,'Finance Tracker'!AF:AF,">="&DATE(2025,1,1),'Finance Tracker'!AF:AF,"<="&DATE(2025,12,31),'Finance Tracker'!F:F,"EV Charger") -> 568230 | R41: =SUMIFS('Finance Tracker'!M:M,'Finance Tracker'!L:L,">="&DATE(2026,1,1),'Finance Tracker'!L:L,"<="&DATE(2026,12,31),'Finance Tracker'!F:F,"EV Charger") +SUMIFS('Finance Tracker'!Q:Q,'Finance Tracker'!P:P,">="&DATE(2026,1,1),'Finance Tracker'!P:P,"<="&DATE(2026,12,31),'Finance Tracker'!F:F,"EV Charger") +SUMIFS('Finance Tracker'!U:U,'Finance Tracker'!T:T,">="&DATE(2026,1,1),'Finance Tracker'!T:T,"<="&DATE(2026,12,31),'Finance Tracker'!F:F,"EV Charger") +SUMIFS('Finance Tracker'!Y:Y,'Finance Tracker'!X:X,">="&DATE(2026,1,1),'Finance Tracker'!X:X,"<="&DATE(2026,12,31),'Finance Tracker'!F:F,"EV Charger") +SUMIFS('Finance Tracker'!AC:AC,'Finance Tracker'!AB:AB,">="&DATE(2026,1,1),'Finance Tracker'!AB:AB,"<="&DATE(2026,12,31),'Finance Tracker'!F:F,"EV Charger") +SUMIFS('Finance Tracker'!AG:AG,'Finance Tracker'!AF:AF,">="&DATE(2026,1,1),'Finance Tracker'!AF:AF,"<="&DATE(2026,12,31),'Finance Tracker'!F:F,"EV Charger") -> 0 | T41: =SUM(U41:X41) -> 735522.5 | U41: =SUMIFS('Finance Tracker'!O:O,'Finance Tracker'!N:N,">="&DATE(2023,1,1),'Finance Tracker'!N:N,"<="&DATE(2023,12,31),'Finance Tracker'!F:F,"EV Charger") +SUMIFS('Finance Tracker'!S:S,'Finance Tracker'!R:R,">="&DATE(2023,1,1),'Finance Tracker'!R:R,"<="&DATE(2023,12,31),'Finance Tracker'!F:F,"EV Charger") +SUMIFS('Finance Tracker'!W:W,'Finance Tracker'!V:V,">="&DATE(2023,1,1),'Finance Tracker'!V:V,"<="&DATE(2023,12,31),'Finance Tracker'!F:F,"EV Charger") +SUMIFS('Finance Tracker'!AA:AA,'Finance Tracker'!Z:Z,">="&DATE(2023,1,1),'Finance Tracker'!Z:Z,"<="&DATE(2023,12,31),'Finance Tracker'!F:F,"EV Charger") +SUMIFS('Finance Tracker'!AD:AD,'Finance Tracker'!AE:AE,">="&DATE(2023,1,1),'Finance Tracker'!AE:AE,"<="&DATE(2023,12,31),'Finance Tracker'!F:F,"EV Charger") +SUMIFS('Finance Tracker'!AI:AI,'Finance Tracker'!AH:AH,">="&DATE(2023,1,1),'Finance Tracker'!AH:AH,"<="&DATE(2023,12,31),'Finance Tracker'!F:F,"EV Charger") -> 46690 | V41: =SUMIFS('Finance Tracker'!O:O,'Finance Tracker'!N:N,">="&DATE(2024,1,1),'Finance Tracker'!N:N,"<="&DATE(2024,12,31),'Finance Tracker'!F:F,"EV Charger") +SUMIFS('Finance Tracker'!S:S,'Finance Tracker'!R:R,">="&DATE(2024,1,1),'Finance Tracker'!R:R,"<="&DATE(2024,12,31),'Finance Tracker'!F:F,"EV Charger") +SUMIFS('Finance Tracker'!W:W,'Finance Tracker'!V:V,">="&DATE(2024,1,1),'Finance Tracker'!V:V,"<="&DATE(2024,12,31),'Finance Tracker'!F:F,"EV Charger") +SUMIFS('Finance Tracker'!AA:AA,'Finance Tracker'!Z:Z,">="&DATE(2024,1,1),'Finance Tracker'!Z:Z,"<="&DATE(2024,12,31),'Finance Tracker'!F:F,"EV Charger") +SUMIFS('Finance Tracker'!AD:AD,'Finance Tracker'!AE:AE,">="&DATE(2024,1,1),'Finance Tracker'!AE:AE,"<="&DATE(2024,12,31),'Finance Tracker'!F:F,"EV Charger") +SUMIFS('Finance Tracker'!AI:AI,'Finance Tracker'!AH:AH,">="&DATE(2024,1,1),'Finance Tracker'!AH:AH,"<="&DATE(2024,12,31),'Finance Tracker'!F:F,"EV Charger") -> 321025 | W41: =SUMIFS('Finance Tracker'!O:O,'Finance Tracker'!N:N,">="&DATE(2025,1,1),'Finance Tracker'!N:N,"<="&DATE(2025,12,31),'Finance Tracker'!F:F,"EV Charger") +SUMIFS('Finance Tracker'!S:S,'Finance Tracker'!R:R,">="&DATE(2025,1,1),'Finance Tracker'!R:R,"<="&DATE(2025,12,31),'Finance Tracker'!F:F,"EV Charger") +SUMIFS('Finance Tracker'!W:W,'Finance Tracker'!V:V,">="&DATE(2025,1,1),'Finance Tracker'!V:V,"<="&DATE(2025,12,31),'Finance Tracker'!F:F,"EV Charger") +SUMIFS('Finance Tracker'!AA:AA,'Finance Tracker'!Z:Z,">="&DATE(2025,1,1),'Finance Tracker'!Z:Z,"<="&DATE(2025,12,31),'Finance Tracker'!F:F,"EV Charger") +SUMIFS('Finance Tracker'!AD:AD,'Finance Tracker'!AE:AE,">="&DATE(2025,1,1),'Finance Tracker'!AE:AE,"<="&DATE(2025,12,31),'Finance Tracker'!F:F,"EV Charger") +SUMIFS('Finance Tracker'!AI:AI,'Finance Tracker'!AH:AH,">="&DATE(2025,1,1),'Finance Tracker'!AH:AH,"<="&DATE(2025,12,31),'Finance Tracker'!F:F,"EV Charger") -> 367807.5 | X41: =SUMIFS('Finance Tracker'!O:O,'Finance Tracker'!N:N,">="&DATE(2026,1,1),'Finance Tracker'!N:N,"<="&DATE(2026,12,31),'Finance Tracker'!F:F,"EV Charger") +SUMIFS('Finance Tracker'!S:S,'Finance Tracker'!R:R,">="&DATE(2026,1,1),'Finance Tracker'!R:R,"<="&DATE(2026,12,31),'Finance Tracker'!F:F,"EV Charger") +SUMIFS('Finance Tracker'!W:W,'Finance Tracker'!V:V,">="&DATE(2026,1,1),'Finance Tracker'!V:V,"<="&DATE(2026,12,31),'Finance Tracker'!F:F,"EV Charger") +SUMIFS('Finance Tracker'!AA:AA,'Finance Tracker'!Z:Z,">="&DATE(2026,1,1),'Finance Tracker'!Z:Z,"<="&DATE(2026,12,31),'Finance Tracker'!F:F,"EV Charger") +SUMIFS('Finance Tracker'!AD:AD,'Finance Tracker'!AE:AE,">="&DATE(2026,1,1),'Finance Tracker'!AE:AE,"<="&DATE(2026,12,31),'Finance Tracker'!F:F,"EV Charger") +SUMIFS('Finance Tracker'!AI:AI,'Finance Tracker'!AH:AH,">="&DATE(2026,1,1),'Finance Tracker'!AH:AH,"<="&DATE(2026,12,31),'Finance Tracker'!F:F,"EV Charger") -> 0 | Z41: =COUNTIF(Table1[Category],"EV Charger") -> 18 | AA41: =COUNTIFS(Table1[Category],"EV Charger",Table1[Closed Date],">="&DATE(2023,1,1),Table1[Closed Date],"<="&DATE(2023,12,31)) -> 1 | AB41: =COUNTIFS(Table1[Category],"EV Charger",Table1[Closed Date],">="&DATE(2024,1,1),Table1[Closed Date],"<="&DATE(2024,12,31)) -> 7 | AC41: =COUNTIFS(Table1[Category],"EV Charger",Table1[Closed Date],">="&DATE(2025,1,1),Table1[Closed Date],"<="&DATE(2025,12,31)) -> 10 | AD41: =COUNTIFS(Table1[Category],"EV Charger",Table1[Closed Date],">="&DATE(2026,1,1),Table1[Closed Date],"<="&DATE(2026,12,31)) -> 0
A42: Total | H42: =SUM(H37:H41) -> 19651384 | I42: =SUM(I37:I41) -> 2117905 | J42: =SUM(J37:J41) -> 9658840.2 | K42: =SUM(K37:K41) -> 7874639 | L42: =SUM(L37:L41) -> 0 | N42: =SUM(N37:N41) -> 17426694 | O42: =SUM(O37:O41) -> 1136750 | P42: =SUM(P37:P41) -> 7171388.2 | Q42: =SUM(Q37:Q41) -> 9118555.8 | R42: =SUM(R37:R41) -> 0 | T42: =SUM(T37:T41) -> 15462552 | U42: =SUM(U37:U41) -> 1059150 | V42: =SUM(V37:V41) -> 6723226.2 | W42: =SUM(W37:W41) -> 7680175.3 | X42: =SUM(X37:X41) -> 0 | Z42: =SUM(Z37:Z41) -> 365 | AA42: =SUM(AA37:AA41) -> 28 | AB42: =SUM(AB37:AB41) -> 168 | AC42: =SUM(AC37:AC41) -> 169 | AD42: =SUM(AD37:AD41) -> 0
B45: System Capacity (kWp) | H45: System Capacity (kWp) | N45: Project Value (RM) | T45: Project Value (RM)
B46: Residential | H46: C&I | N46: Residential | T46: C&I
B47: Total | C47: 2023 | D47: 2024 | E47: 2025 | F47: 2026 | H47: Total | I47: 2023 | J47: 2024 | K47: 2025 | L47: 2026 | N47: Total | O47: 2023 | P47: 2024 | Q47: 2025 | R47: 2026 | T47: Total | U47: 2023 | V47: 2024 | W47: 2025 | X47: 2026
A48: NEM | B48: =SUMIFS(Table1[PV System Capacity (kWp)],Table1[Scheme],"NEM",Table1[Category],"*R*") -> 3417.375 | C48: =SUMIFS(Table1[PV System Capacity (kWp)],Table1[Scheme],"NEM",Table1[Category],"*R*",Table1[Closed Date],">="&DATE(2023,1,1),Table1[Closed Date],"<="&DATE(2023,12,31)) -> 220.15 | D48: =SUMIFS(Table1[PV System Capacity (kWp)],Table1[Scheme],"NEM",Table1[Category],"*R*",Table1[Closed Date],">="&DATE(2024,1,1),Table1[Closed Date],"<="&DATE(2024,12,31)) -> 1637.165 | E48: =SUMIFS(Table1[PV System Capacity (kWp)],Table1[Scheme],"NEM",Table1[Category],"*R*",Table1[Closed Date],">="&DATE(2025,1,1),Table1[Closed Date],"<="&DATE(2025,12,31)) -> 1560.06 | F48: =SUMIFS(Table1[PV System Capacity (kWp)],Table1[Scheme],"NEM",Table1[Category],"*R*",Table1[Closed Date],">="&DATE(2026,1,1),Table1[Closed Date],"<="&DATE(2026,12,31)) -> 0 | H48: =SUMIFS(Table1[PV System Capacity (kWp)],Table1[Scheme],"NEM",Table1[Category],"*C&I*") -> 3286.685 | I48: =SUMIFS(Table1[PV System Capacity (kWp)],Table1[Scheme],"NEM",Table1[Category],"*C&I*",Table1[Closed Date],">="&DATE(2023,1,1),Table1[Closed Date],"<="&DATE(2023,12,31)) -> 428.695 | J48: =SUMIFS(Table1[PV System Capacity (kWp)],Table1[Scheme],"NEM",Table1[Category],"*C&I*",Table1[Closed Date],">="&DATE(2024,1,1),Table1[Closed Date],"<="&DATE(2024,12,31)) -> 1675 | K48: =SUMIFS(Table1[PV System Capacity (kWp)],Table1[Scheme],"NEM",Table1[Category],"*C&I*",Table1[Closed Date],">="&DATE(2025,1,1),Table1[Closed Date],"<="&DATE(2025,12,31)) -> 1182.99 | L48: =SUMIFS(Table1[PV System Capacity (kWp)],Table1[Scheme],"NEM",Table1[Category],"*C&I*",Table1[Closed Date],">="&DATE(2026,1,1),Table1[Closed Date],"<="&DATE(2026,12,31)) -> 0 | N48: =SUMIFS(Table1[Project Value (RM)],Table1[Scheme],"NEM",Table1[Category],"*R*") -> 9838567.6 | O48: =SUMIFS(Table1[Project Value (RM)],Table1[Scheme],"NEM",Table1[Category],"*R*",Table1[Closed Date],">="&DATE(2023,1,1),Table1[Closed Date],"<="&DATE(2023,12,31)) -> 751725 | P48: =SUMIFS(Table1[Project Value (RM)],Table1[Scheme],"NEM",Table1[Category],"*R*",Table1[Closed Date],">="&DATE(2024,1,1),Table1[Closed Date],"<="&DATE(2024,12,31)) -> 5036797.2 | Q48: =SUMIFS(Table1[Project Value (RM)],Table1[Scheme],"NEM",Table1[Category],"*R*",Table1[Closed Date],">="&DATE(2025,1,1),Table1[Closed Date],"<="&DATE(2025,12,31)) -> 4050045.4 | R48: =SUMIFS(Table1[Project Value (RM)],Table1[Scheme],"NEM",Table1[Category],"*R*",Table1[Closed Date],">="&DATE(2026,1,1),Table1[Closed Date],"<="&DATE(2026,12,31)) -> 0 | T48: =SUMIFS(Table1[Project Value (RM)],Table1[Scheme],"NEM",Table1[Category],"*C&I*") -> 6721700 | U48: =SUMIFS(Table1[Project Value (RM)],Table1[Scheme],"NEM",Table1[Category],"*C&I*",Table1[Closed Date],">="&DATE(2023,1,1),Table1[Closed Date],"<="&DATE(2023,12,31)) -> 521800 | V48: =SUMIFS(Table1[Project Value (RM)],Table1[Scheme],"NEM",Table1[Category],"*C&I*",Table1[Closed Date],">="&DATE(2024,1,1),Table1[Closed Date],"<="&DATE(2024,12,31)) -> 3866600 | W48: =SUMIFS(Table1[Project Value (RM)],Table1[Scheme],"NEM",Table1[Category],"*C&I*",Table1[Closed Date],">="&DATE(2025,1,1),Table1[Closed Date],"<="&DATE(2025,12,31)) -> 2333300 | X48: =SUMIFS(Table1[Project Value (RM)],Table1[Scheme],"NEM",Table1[Category],"*C&I*",Table1[Closed Date],">="&DATE(2026,1,1),Table1[Closed Date],"<="&DATE(2026,12,31)) -> 0
A49: SELCO | B49: =SUMIFS(Table1[PV System Capacity (kWp)],Table1[Scheme],"SELCO",Table1[Category],"*R*") -> 217.77 | C49: =SUMIFS(Table1[PV System Capacity (kWp)],Table1[Scheme],"SELCO",Table1[Category],"*R*",Table1[Closed Date],">="&DATE(2023,1,1),Table1[Closed Date],"<="&DATE(2023,12,31)) -> 93.15 | D49: =SUMIFS(Table1[PV System Capacity (kWp)],Table1[Scheme],"SELCO",Table1[Category],"*R*",Table1[Closed Date],">="&DATE(2024,1,1),Table1[Closed Date],"<="&DATE(2024,12,31)) -> 0 | E49: =SUMIFS(Table1[PV System Capacity (kWp)],Table1[Scheme],"SELCO",Table1[Category],"*R*",Table1[Closed Date],">="&DATE(2025,1,1),Table1[Closed Date],"<="&DATE(2025,12,31)) -> 124.62 | F49: =SUMIFS(Table1[PV System Capacity (kWp)],Table1[Scheme],"SELCO",Table1[Category],"*R*",Table1[Closed Date],">="&DATE(2026,1,1),Table1[Closed Date],"<="&DATE(2026,12,31)) -> 0 | H49: =SUMIFS(Table1[PV System Capacity (kWp)],Table1[Scheme],"SELCO",Table1[Category],"*C&I*") -> 431.325 | I49: =SUMIFS(Table1[PV System Capacity (kWp)],Table1[Scheme],"SELCO",Table1[Category],"*C&I*",Table1[Closed Date],">="&DATE(2023,1,1),Table1[Closed Date],"<="&DATE(2023,12,31)) -> 0 | J49: =SUMIFS(Table1[PV System Capacity (kWp)],Table1[Scheme],"SELCO",Table1[Category],"*C&I*",Table1[Closed Date],">="&DATE(2024,1,1),Table1[Closed Date],"<="&DATE(2024,12,31)) -> 413.345 | K49: =SUMIFS(Table1[PV System Capacity (kWp)],Table1[Scheme],"SELCO",Table1[Category],"*C&I*",Table1[Closed Date],">="&DATE(2025,1,1),Table1[Closed Date],"<="&DATE(2025,12,31)) -> 17.98 | L49: =SUMIFS(Table1[PV System Capacity (kWp)],Table1[Scheme],"SELCO",Table1[Category],"*C&I*",Table1[Closed Date],">="&DATE(2026,1,1),Table1[Closed Date],"<="&DATE(2026,12,31)) -> 0 | N49: =SUMIFS(Table1[Project Value (RM)],Table1[Scheme],"SELCO",Table1[Category],"*R*") -> 1196300 | O49: =SUMIFS(Table1[Project Value (RM)],Table1[Scheme],"SELCO",Table1[Category],"*R*",Table1[Closed Date],">="&DATE(2023,1,1),Table1[Closed Date],"<="&DATE(2023,12,31)) -> 751000 | P49: =SUMIFS(Table1[Project Value (RM)],Table1[Scheme],"SELCO",Table1[Category],"*R*",Table1[Closed Date],">="&DATE(2024,1,1),Table1[Closed Date],"<="&DATE(2024,12,31)) -> 0 | Q49: =SUMIFS(Table1[Project Value (RM)],Table1[Scheme],"SELCO",Table1[Category],"*R*",Table1[Closed Date],">="&DATE(2025,1,1),Table1[Closed Date],"<="&DATE(2025,12,31)) -> 445300 | R49: =SUMIFS(Table1[Project Value (RM)],Table1[Scheme],"SELCO",Table1[Category],"*R*",Table1[Closed Date],">="&DATE(2026,1,1),Table1[Closed Date],"<="&DATE(2026,12,31)) -> 0 | T49: =SUMIFS(Table1[Project Value (RM)],Table1[Scheme],"SELCO",Table1[Category],"*C&I*") -> 463853.58 | U49: =SUMIFS(Table1[Project Value (RM)],Table1[Scheme],"SELCO",Table1[Category],"*C&I*",Table1[Closed Date],">="&DATE(2023,1,1),Table1[Closed Date],"<="&DATE(2023,12,31)) -> 0 | V49: =SUMIFS(Table1[Project Value (RM)],Table1[Scheme],"SELCO",Table1[Category],"*C&I*",Table1[Closed Date],">="&DATE(2024,1,1),Table1[Closed Date],"<="&DATE(2024,12,31)) -> 400080 | W49: =SUMIFS(Table1[Project Value (RM)],Table1[Scheme],"SELCO",Table1[Category],"*C&I*",Table1[Closed Date],">="&DATE(2025,1,1),Table1[Closed Date],"<="&DATE(2025,12,31)) -> 63773.58 | X49: =SUMIFS(Table1[Project Value (RM)],Table1[Scheme],"SELCO",Table1[Category],"*C&I*",Table1[Closed Date],">="&DATE(2026,1,1),Table1[Closed Date],"<="&DATE(2026,12,31)) -> 0
